#VRML_SIM R2023b utf8

EXTERNPROTO "https://raw.githubusercontent.com/cyberbotics/webots/R2023b/projects/objects/backgrounds/protos/TexturedBackground.proto"
EXTERNPROTO "https://raw.githubusercontent.com/cyberbotics/webots/R2023b/projects/objects/backgrounds/protos/TexturedBackgroundLight.proto"
EXTERNPROTO "https://raw.githubusercontent.com/cyberbotics/webots/R2023b/projects/objects/floors/protos/RectangleArena.proto"

WorldInfo {
}
Viewpoint {
  orientation 0.3492255631016862 0.5447513081236879 -0.762422139220682 2.0025232808361806
  position 2.9258928827833373 1.4574860154007363 2.9017948178509125
}
TexturedBackground {
}
TexturedBackgroundLight {
}
RectangleArena {
  translation -0.02 0 9.38568e-08
  rotation 0 1 0 4.692820414042842e-06
  floorSize 10 10
}
Robot {
  translation 2.8083731702954866 0.19678366261474603 0.052011388707013356
  rotation 0.031089218630181516 0.016566759934891807 0.9993793088463582 0.9841101100724171
  children [
    DEF distance_sensor Solid {
      translation 0 0.18 0.02
      rotation 1 0 0 1.5708
      children [
        DEF distance_sensor Shape {
          appearance PBRAppearance {
            baseColor 0.9 1 1
            roughness 1
            metalness 0
          }
          geometry Cylinder {
            height 0.01
            radius 0.01
          }
        }
        DistanceSensor {
          rotation 0 -1 0 -1.5707953071795862
          name "ds_front_1"
        }
      ]
      name "ds_back_1"
      boundingObject USE distance_sensor
      physics Physics {
      }
    }
    DEF distance_sensor Solid {
      translation 0 -0.18 0.02
      rotation 1 0 0 1.5708
      children [
        DEF distance_sensor Shape {
          appearance PBRAppearance {
            baseColor 0.9 1 1
            roughness 1
            metalness 0
          }
          geometry Cylinder {
            height 0.01
            radius 0.01
          }
        }
        DistanceSensor {
          rotation 0 1 0 -1.5707953071795862
          name "ds_front_1"
        }
      ]
      name "sensor_solid"
      boundingObject USE distance_sensor
      physics Physics {
      }
    }
    DEF Body Solid {
      children [
        DEF Body Pose {
          children [
            Shape {
              appearance PBRAppearance {
                baseColor 0 0.1 0.4
                roughness 1
                metalness 0
              }
              geometry Cylinder {
                height 0.09
                radius 0.18
              }
            }
          ]
        }
      ]
    }
    HingeJoint {
      jointParameters HingeJointParameters {
        position 213.55398533935028
        anchor 0.17 0 0.01
      }
      device [
        RotationalMotor {
          name "motor_1"
        }
      ]
      endPoint Solid {
        translation 0.17051543715123266 -2.821136428339886e-05 0.010006941623586863
        rotation -0.5903968005576863 -0.5495666425729747 0.5911075395072507 2.140159431739387
        children [
          DEF wheel Shape {
            appearance PBRAppearance {
              baseColor 0.9 0.9 0
              metalness 0
            }
            geometry Cylinder {
              height 0.026
              radius 0.066
            }
          }
        ]
        name "solid(1)"
        boundingObject USE wheel
        physics DEF wheel_physics Physics {
        }
        linearVelocity 0.27123893868514204 -0.179558439112272 -2.518771179914347e-06
        angularVelocity 2.7320496540273367 4.128074982685695 -0.13246995962652083
      }
    }
    HingeJoint {
      jointParameters HingeJointParameters {
        position 80.86608133618537
        anchor -0.17 0 0.01
      }
      device [
        RotationalMotor {
          name "motor_2"
        }
      ]
      endPoint Solid {
        translation -0.17052340309558034 6.200781007587823e-05 0.01005500926539667
        rotation -0.3689685311658963 -0.8532829658412476 0.3684703559507131 1.727599671072686
        children [
          USE wheel
        ]
        name "solid(2)"
        boundingObject USE wheel
        physics USE wheel_physics
        linearVelocity 0.23504153098962272 -0.15557512498052536 -2.5842621332569345e-06
        angularVelocity 2.3463691956635375 3.54391594508066 -0.13161991340638077
      }
    }
  ]
  boundingObject Cylinder {
    height 0.09
    radius 0.18
  }
  physics Physics {
  }
  controller "my_controller"
  linearVelocity 0.2526379006131757 -0.16717147714489733 -5.7102764988364053e-05
  angularVelocity 0.028840693435309414 0.041184952976314505 -0.12784503915089312
}
