#VRML_SIM R2023b utf8

EXTERNPROTO "https://raw.githubusercontent.com/cyberbotics/webots/R2023b/projects/objects/backgrounds/protos/TexturedBackground.proto"
EXTERNPROTO "https://raw.githubusercontent.com/cyberbotics/webots/R2023b/projects/objects/backgrounds/protos/TexturedBackgroundLight.proto"
EXTERNPROTO "https://raw.githubusercontent.com/cyberbotics/webots/R2023b/projects/objects/floors/protos/RectangleArena.proto"

WorldInfo {
}
Viewpoint {
  orientation 0.20901698299329052 -0.959626574453511 0.188225233226054 5.233640896264354
  position 2.2160654718467336 -0.3394634083190828 0.599077286096239
}
TexturedBackground {
}
TexturedBackgroundLight {
}
RectangleArena {
  translation -0.02 0 9.38568e-08
  rotation 0 1 0 4.692820414042842e-06
  floorSize 10 10
}
Robot {
  translation 2.602594735585539 -0.46388855536515095 0.05201732807150444
  rotation -0.0022375755353461705 0.0009448811263832534 -0.9999970502233397 1.1888244597337232
  children [
    DEF distance_sensor Solid {
      translation -0.085 -0.16 0.02
      rotation -0.9351132545462786 0.25056206820525934 0.25056306820553154 -1.6378353071795866
      children [
        DEF distance_sensor Shape {
          appearance PBRAppearance {
            baseColor 0.9 1 1
            roughness 1
            metalness 0
          }
          geometry Cylinder {
            height 0.01
            radius 0.01
          }
        }
        DistanceSensor {
          rotation 0 1 0 -1.5707953071795862
          name "ds_front_right"
        }
      ]
      name "ds_front_right"
      boundingObject USE distance_sensor
      physics Physics {
      }
    }
    DEF distance_sensor Solid {
      translation 0.085 -0.16 0.02
      rotation 0.9351132545462786 0.25056206820525934 0.25056306820553154 1.63784
      children [
        DEF distance_sensor Shape {
          appearance PBRAppearance {
            baseColor 0.9 1 1
            roughness 1
            metalness 0
          }
          geometry Cylinder {
            height 0.01
            radius 0.01
          }
        }
        DistanceSensor {
          rotation 0 1 0 -1.5707953071795862
          name "ds_front_left"
        }
      ]
      name "ds_front_left"
      boundingObject USE distance_sensor
      physics Physics {
      }
    }
    DEF distance_sensor Solid {
      translation -0.085 0.16 0.0199991
      rotation 0.9351132545462786 0.25056206820525934 0.25056306820553154 1.63784
      children [
        DEF distance_sensor Shape {
          appearance PBRAppearance {
            baseColor 0.9 1 1
            roughness 1
            metalness 0
          }
          geometry Cylinder {
            height 0.01
            radius 0.01
          }
        }
        DistanceSensor {
          rotation 0 -1 0 -1.5707953071795862
          name "ds_back_left"
        }
      ]
      name "ds_back_left"
      boundingObject USE distance_sensor
      physics Physics {
      }
    }
    DEF distance_sensor Solid {
      translation 0.085 0.16 0.02
      rotation -0.9351132545462786 0.25056206820525934 0.25056306820553154 -1.6378353071795866
      children [
        DEF distance_sensor Shape {
          appearance PBRAppearance {
            baseColor 0.9 1 1
            roughness 1
            metalness 0
          }
          geometry Cylinder {
            height 0.01
            radius 0.01
          }
        }
        DistanceSensor {
          rotation 0 -1 0 -1.5707953071795862
          name "ds_back_right"
        }
      ]
      name "ds_back_right"
      boundingObject USE distance_sensor
      physics Physics {
      }
    }
    DEF distance_sensor Solid {
      translation 0 0.18 0.02
      rotation 1 0 0 1.5708
      children [
        DEF distance_sensor Shape {
          appearance PBRAppearance {
            baseColor 0.9 1 1
            roughness 1
            metalness 0
          }
          geometry Cylinder {
            height 0.01
            radius 0.01
          }
        }
        DistanceSensor {
          rotation 0 -1 0 -1.5707953071795862
          name "ds_back_middle"
        }
      ]
      name "ds_back_middle"
      boundingObject USE distance_sensor
      physics Physics {
      }
    }
    DEF distance_sensor Solid {
      translation 0 -0.18 0.02
      rotation 1 0 0 1.5708
      children [
        DEF distance_sensor Shape {
          appearance PBRAppearance {
            baseColor 0.9 1 1
            roughness 1
            metalness 0
          }
          geometry Cylinder {
            height 0.01
            radius 0.01
          }
        }
        DistanceSensor {
          rotation 0 1 0 -1.5707953071795862
          name "ds_front_middle"
        }
      ]
      name "front_middle_sensor"
      boundingObject USE distance_sensor
      physics Physics {
      }
    }
    DEF Body Solid {
      children [
        DEF Body Pose {
          children [
            Shape {
              appearance PBRAppearance {
                baseColor 0 0.1 0.4
                roughness 1
                metalness 0
              }
              geometry Cylinder {
                height 0.09
                radius 0.18
              }
            }
          ]
        }
      ]
    }
    HingeJoint {
      jointParameters HingeJointParameters {
        position 282.7162751098908
        anchor 0.17 0 0.01
      }
      device [
        RotationalMotor {
          name "motor_1"
        }
      ]
      endPoint Solid {
        translation 0.17070888513689342 -4.2081842914518734e-05 0.009935331011483476
        rotation 0.5842297922887738 0.5679139563017037 -0.5797838287154641 4.170160263619587
        children [
          DEF wheel Shape {
            appearance PBRAppearance {
              baseColor 0.9 0.9 0
              metalness 0
            }
            geometry Cylinder {
              height 0.026
              radius 0.066
            }
          }
        ]
        name "solid(1)"
        boundingObject USE wheel
        physics DEF wheel_physics Physics {
        }
        linearVelocity -0.2823884221313961 -0.11688440588352572 -2.5680594550107428e-05
        angularVelocity 1.8206559157148503 -4.3597120425153815 -0.6570489109375177
      }
    }
    HingeJoint {
      jointParameters HingeJointParameters {
        position 100.66423908038841
        anchor -0.17 0 0.01
      }
      device [
        RotationalMotor {
          name "motor_2"
        }
      ]
      endPoint Solid {
        translation -0.17071918891533222 -7.359699127024955e-05 0.010119915488065642
        rotation 0.06748539943480347 -0.995567792170291 -0.06550184773193252 1.5729037977733435
        children [
          USE wheel
        ]
        name "solid(2)"
        boundingObject USE wheel
        physics USE wheel_physics
        linearVelocity -0.08218770674352781 -0.03398434856207558 -0.000160078923386515
        angularVelocity 0.467157202478398 -1.1319567728906772 -0.6373293490530484
      }
    }
  ]
  boundingObject Cylinder {
    height 0.09
    radius 0.18
  }
  physics Physics {
  }
  controller "my_controller"
  linearVelocity -0.183961409798919 -0.07627324954770784 4.4535016055898574e-05
  angularVelocity -0.06856751952980684 0.16156289363469145 -0.6354403205969007
}
