#VRML_SIM R2023b utf8

EXTERNPROTO "https://raw.githubusercontent.com/cyberbotics/webots/R2023b/projects/objects/backgrounds/protos/TexturedBackground.proto"
EXTERNPROTO "https://raw.githubusercontent.com/cyberbotics/webots/R2023b/projects/objects/backgrounds/protos/TexturedBackgroundLight.proto"
EXTERNPROTO "https://raw.githubusercontent.com/cyberbotics/webots/R2023b/projects/objects/floors/protos/RectangleArena.proto"

WorldInfo {
}
Viewpoint {
  orientation -0.3658255953523802 -0.3375537201026558 0.8673114318570547 4.4914267511230435
  position -0.1274767989323618 1.0533584536201532 1.0447897859804351
}
TexturedBackground {
}
TexturedBackgroundLight {
}
RectangleArena {
  rotation 0 1 0 4.692820414042842e-06
}
Solid {
  children [
    Transform {
      rotation 1 0 0 1.55
      scale 0.001 0.001 0.001
      children [
        Shape {
          appearance PBRAppearance {
          }
          geometry Mesh {
            url [
              "Ensamblaje_Base_webots.STL"
            ]
          }
        }
      ]
    }
  ]
  name "Base"
}
Robot {
  children [
    DEF Body Transform {
      translation -0.28 0 0
      rotation 1 0 0 1.5708
      scale 0.001 0.001 0.001
      children [
        Shape {
          appearance PBRAppearance {
          }
          geometry Mesh {
            url [
              "Ensamblaje_Base_webots.STL"
            ]
          }
        }
      ]
    }
    HingeJoint {
      jointParameters HingeJointParameters {
      }
      device [
        DEF motor_1 RotationalMotor {
        }
      ]
      endPoint Solid {
        rotation 0 1 0 -1.5707953071795862
        children [
          Transform {
            scale 0.001 0.001 0.001
            children [
              Shape {
                appearance PBRAppearance {
                }
                geometry Mesh {
                  url [
                    "Rueda_Webots.STL"
                  ]
                }
              }
            ]
          }
        ]
      }
    }
  ]
  physics Physics {
  }
}
DEF Wheel_1 Solid {
  translation -0.00999979 -0.087 0.0699999
  rotation -0.577349935856137 0.5773509358560258 -0.577349935856137 2.09439
  children [
    Transform {
      scale 0.001 0.001 0.001
      children [
        Shape {
          appearance PBRAppearance {
          }
          geometry Mesh {
            url [
              "Rueda_Webots.STL"
            ]
          }
        }
      ]
    }
  ]
  name "Wheel_1"
}
DEF Wheel_2 Solid {
  translation 0.18 -0.16 -8.15696e-08
  rotation 0 1 0 -1.5707953071795862
  children [
    Transform {
      scale 0.001 0.001 0.001
      children [
        Shape {
          appearance PBRAppearance {
          }
          geometry Mesh {
            url [
              "Rueda_Webots.STL"
            ]
          }
        }
      ]
    }
  ]
  name "Wheel_2"
}
