#VRML_SIM R2023b utf8

EXTERNPROTO "https://raw.githubusercontent.com/cyberbotics/webots/R2023b/projects/objects/backgrounds/protos/TexturedBackground.proto"
EXTERNPROTO "https://raw.githubusercontent.com/cyberbotics/webots/R2023b/projects/objects/backgrounds/protos/TexturedBackgroundLight.proto"
EXTERNPROTO "https://raw.githubusercontent.com/cyberbotics/webots/R2023b/projects/objects/floors/protos/RectangleArena.proto"

WorldInfo {
}
Viewpoint {
  orientation 0.4016263092334565 -0.17837251182894043 -0.8982647464725232 5.1254644850173765
  position -0.5878474781579627 -1.0848952941552001 0.561992188449627
}
TexturedBackground {
}
TexturedBackgroundLight {
}
RectangleArena {
  translation -0.02 0 9.38568e-08
  rotation 0 1 0 4.692820414042842e-06
  floorSize 10 10
}
Robot {
  translation -9.55826892509974e-07 -0.5747181705690151 0.05205938134768939
  rotation -0.9999999667976598 0.00019009399140280424 -0.0001739797515614751 0.033010757238413145
  children [
    DEF Body Solid {
      children [
        DEF Body Transform {
          children [
            Shape {
              appearance PBRAppearance {
                baseColor 0 0.1 0.4
                roughness 1
                metalness 0
              }
              geometry Cylinder {
                height 0.09
                radius 0.18
              }
            }
          ]
        }
      ]
    }
    HingeJoint {
      jointParameters HingeJointParameters {
        position 8.72682646168375
        anchor 0.17 0 0.01
      }
      device [
        RotationalMotor {
          name "motor_1"
        }
      ]
      endPoint Solid {
        translation 0.17 0 0.01
        rotation -0.3896117750671712 0.8346555371034214 0.38929782829038156 4.533414265597015
        children [
          DEF wheel Shape {
            appearance PBRAppearance {
              baseColor 0.9 0.9 0
              metalness 0
            }
            geometry Cylinder {
              height 0.026
              radius 0.066
            }
          }
        ]
        name "solid(1)"
        boundingObject USE wheel
        physics DEF wheel_physics Physics {
        }
        linearVelocity -1.1519275184730338e-06 -0.22609695808450142 -5.754264479146843e-07
        angularVelocity 3.425701969645581 -1.7553191283174216e-05 -2.5171922616291786e-05
      }
    }
    HingeJoint {
      jointParameters HingeJointParameters {
        position 8.726826286306466
        anchor -0.17 0 0.01
      }
      device [
        RotationalMotor {
          name "motor_2"
        }
      ]
      endPoint Solid {
        translation -0.17 0 0.01
        rotation -0.6848033622837177 0.24917798120533588 0.6848026640480809 3.630002829746387
        children [
          USE wheel
        ]
        name "solid(2)"
        boundingObject USE wheel
        physics USE wheel_physics
        linearVelocity -1.1401162185752483e-06 -0.22609496838332743 2.914399112609254e-07
        angularVelocity 3.425701704492191 -1.7210672410313647e-05 -2.5140640195169754e-05
      }
    }
  ]
  boundingObject Cylinder {
    height 0.09
    radius 0.18
  }
  physics Physics {
  }
  controller "my_controller"
  linearVelocity -1.1776274650184884e-06 -0.2268382574159628 2.4162773275657062e-05
  angularVelocity -0.07429811608576625 3.044078066472244e-06 -3.381746369181926e-06
}
