#VRML_SIM R2023b utf8

EXTERNPROTO "https://raw.githubusercontent.com/cyberbotics/webots/R2023b/projects/objects/backgrounds/protos/TexturedBackground.proto"
EXTERNPROTO "https://raw.githubusercontent.com/cyberbotics/webots/R2023b/projects/objects/backgrounds/protos/TexturedBackgroundLight.proto"
EXTERNPROTO "https://raw.githubusercontent.com/cyberbotics/webots/R2023b/projects/objects/floors/protos/RectangleArena.proto"

WorldInfo {
}
Viewpoint {
  orientation 0.279332589735195 0.23418402270997327 -0.9311987692320067 2.631335762278998
  position 0.4582127529259449 -0.10844052010565286 0.9658699396698791
}
TexturedBackground {
}
TexturedBackgroundLight {
}
RectangleArena {
  translation -0.02 0 9.38568e-08
  rotation 0 1 0 4.692820414042842e-06
  floorSize 10 10
}
Robot {
  translation -0.4477219132141394 -0.44827518316115134 0.05205764160299552
  rotation 9.350628351819684e-05 0.0004764753714549279 0.9999998821138908 2.57670711911489
  children [
    Solid {
      translation 0 -0.18 0.02
      rotation 1 0 0 1.5708
      children [
        DEF distance_sensor Shape {
          appearance PBRAppearance {
            baseColor 0.9 1 1
            roughness 1
            metalness 0
          }
          geometry Cylinder {
            height 0.01
            radius 0.01
          }
        }
        DistanceSensor {
          rotation 0 1 0 -1.5707953071795862
          name "ds_front_1"
        }
      ]
      name "sensor_solid"
      boundingObject USE distance_sensor
      physics Physics {
      }
    }
    DEF Body Solid {
      children [
        DEF Body Pose {
          children [
            Shape {
              appearance PBRAppearance {
                baseColor 0 0.1 0.4
                roughness 1
                metalness 0
              }
              geometry Cylinder {
                height 0.09
                radius 0.18
              }
            }
          ]
        }
      ]
    }
    HingeJoint {
      jointParameters HingeJointParameters {
        position 72.72504004137303
        anchor 0.17 0 0.01
      }
      device [
        RotationalMotor {
          name "motor_1"
        }
      ]
      endPoint Solid {
        translation 0.17025055019171723 2.0238539969019698e-05 0.010062012964464746
        rotation 0.6484708590604723 -0.39627128390324917 -0.649965087141643 2.3772124285803384
        children [
          DEF wheel Shape {
            appearance PBRAppearance {
              baseColor 0.9 0.9 0
              metalness 0
            }
            geometry Cylinder {
              height 0.026
              radius 0.066
            }
          }
        ]
        name "solid(1)"
        boundingObject USE wheel
        physics DEF wheel_physics Physics {
        }
      }
    }
    HingeJoint {
      jointParameters HingeJointParameters {
        position 17.888050287821617
        anchor -0.17 0 0.01
      }
      device [
        RotationalMotor {
          name "motor_2"
        }
      ]
      endPoint Solid {
        translation -0.17025376284419716 -2.0628965826885448e-05 0.010081828914098832
        rotation 0.4195702791941203 0.8045805006976552 -0.4202511138760713 -1.7852941242360094
        children [
          USE wheel
        ]
        name "solid(2)"
        boundingObject USE wheel
        physics USE wheel_physics
      }
    }
  ]
  boundingObject Cylinder {
    height 0.09
    radius 0.18
  }
  physics Physics {
  }
  controller "my_controller"
  linearVelocity 0.09500996988667856 0.15632075818341729 -1.1420004520842463e-06
  angularVelocity 0.02690046099502572 -0.01660043018958586 -0.7600991256721067
}
