#VRML_SIM R2023b utf8

EXTERNPROTO "https://raw.githubusercontent.com/cyberbotics/webots/R2023b/projects/objects/backgrounds/protos/TexturedBackground.proto"
EXTERNPROTO "https://raw.githubusercontent.com/cyberbotics/webots/R2023b/projects/objects/backgrounds/protos/TexturedBackgroundLight.proto"
EXTERNPROTO "https://raw.githubusercontent.com/cyberbotics/webots/R2023b/projects/objects/floors/protos/RectangleArena.proto"

WorldInfo {
}
Viewpoint {
  orientation 0.025991916544447134 0.4040884345837591 -0.9143505658717522 1.3745441529815743
  position -17.72788406907057 280.6325940827747 117.95647263469768
}
TexturedBackground {
}
TexturedBackgroundLight {
}
RectangleArena {
  translation -0.0199931 0 1.33
  rotation 0 -1 0 -5.307179586466759e-06
  floorSize 1000 1000
  floorTileSize 100 100
  wallThickness 0.011
  wallHeight 100
}
Robot {
  translation -34.5783 0.032323 -13.3641
  rotation -0.6483261307123528 0.14714387469279638 0.7470086400945707 0.00040243026828830765
  children [
    HingeJoint {
      jointParameters HingeJointParameters {
        position 0.10999735885653747
      }
      device [
        DEF motor_1 RotationalMotor {
          name "motor_1"
        }
      ]
      endPoint Solid {
        translation 0.10000001569635941 -0.04085427428029015 0.00553294282466457
        rotation 0.05488745509883229 -0.9969828233962287 -0.05488731297538592 1.573815470451399
        children [
          Transform {
            scale 0.001 0.001 0.001
            children [
              DEF wheel Shape {
                appearance PBRAppearance {
                }
                geometry Mesh {
                  url [
                    "Rueda_Webots.STL"
                  ]
                }
              }
            ]
          }
        ]
        boundingObject Pose {
        }
        physics DEF wheel_physics Physics {
        }
        linearVelocity 7.688956034368919e-11 6.615233100230372e-08 3.649009038326701e-07
        angularVelocity -1.1944762198604351e-05 8.590142366832716e-09 7.205261246583605e-10
      }
    }
    HingeJoint {
      jointParameters HingeJointParameters {
        position 0.11253720822609528
      }
      device [
        RotationalMotor {
          name "motor_2"
        }
      ]
      endPoint Solid {
        translation -0.09000011301022677 -0.04872902281850056 0.07498580470755592
        rotation 0.0561493718201315 0.9968422552408579 0.05614949875577915 1.5739613230304397
        children [
          Transform {
            scale 0.001 0.001 0.001
            children [
              USE wheel
            ]
          }
        ]
        name "solid(1)"
        physics USE wheel_physics
        linearVelocity -4.434364720903138e-10 -1.4266350246777202e-06 -1.0489311284232057e-06
        angularVelocity 1.9031670260284674e-05 -5.1578269498168515e-09 -1.16423450014838e-09
      }
    }
    Pose {
      children [
        Pose {
        }
      ]
    }
    DEF Body Pose {
      translation -0.08 0.12 4.40784e-07
      rotation 1 0 0 1.5708
      children [
        Shape {
          appearance PBRAppearance {
          }
          geometry Mesh {
            url [
              "Ensamblaje_Base_webots.STL"
            ]
          }
        }
      ]
    }
  ]
  boundingObject USE Body
  controller "my_controller"
}
DEF Wheel_1 Solid {
  translation -44 -90 70
  rotation -0.577349935856137 0.5773509358560258 -0.577349935856137 2.09439
  children [
    Pose {
      children [
        Shape {
          appearance PBRAppearance {
          }
          geometry Mesh {
            url [
              "Rueda_Webots.STL"
            ]
          }
        }
      ]
    }
  ]
  name "Wheel_1"
  boundingObject USE wheel
}
DEF Wheel_2 Solid {
  translation 142.42 -162.24 -5
  rotation 0 1 0 -1.5707953071795862
  children [
    Pose {
      children [
        Shape {
          appearance PBRAppearance {
          }
          geometry Mesh {
            url [
              "Rueda_Webots.STL"
            ]
          }
        }
      ]
    }
  ]
  name "Wheel_2"
  boundingObject USE wheel
}
